2024-10-24 07:31:20,903 ERROR frappe New Exception collected with id: 2024-10-24 07:31:20.854059-127.0.0.1-42c
Site: erpnext.localhost
Form Dict: {}
2024-10-24 07:31:20,906 ERROR frappe Failed to run after request hook
Site: erpnext.localhost
Form Dict: {}
Traceback (most recent call last):
  File "/workspace/development/frappe-bench/apps/frappe/frappe/app.py", line 84, in application
    init_request(request)
  File "/workspace/development/frappe-bench/apps/frappe/frappe/app.py", line 172, in init_request
    frappe.local.http_request = frappe.auth.HTTPRequest()
  File "/workspace/development/frappe-bench/apps/frappe/frappe/auth.py", line 35, in __init__
    self.set_session()
  File "/workspace/development/frappe-bench/apps/frappe/frappe/auth.py", line 71, in set_session
    frappe.local.login_manager = LoginManager()
  File "/workspace/development/frappe-bench/apps/frappe/frappe/auth.py", line 120, in __init__
    self.make_session(resume=True)
  File "/workspace/development/frappe-bench/apps/frappe/frappe/auth.py", line 208, in make_session
    frappe.local.session_obj = Session(
  File "/workspace/development/frappe-bench/apps/frappe/frappe/sessions.py", line 230, in __init__
    self.resume()
  File "/workspace/development/frappe-bench/apps/frappe/frappe/sessions.py", line 308, in resume
    validate_ip_address(self.user)
  File "/workspace/development/frappe-bench/apps/frappe/frappe/auth.py", line 422, in validate_ip_address
    frappe.get_cached_value("User", user, user_fields, as_dict=True)
  File "/workspace/development/frappe-bench/apps/frappe/frappe/__init__.py", line 1165, in get_cached_value
    doc = get_cached_doc(doctype, name)
  File "/workspace/development/frappe-bench/apps/frappe/frappe/__init__.py", line 1106, in get_cached_doc
    doc = get_doc(*args, **kwargs)
  File "/workspace/development/frappe-bench/apps/frappe/frappe/__init__.py", line 1199, in get_doc
    doc = frappe.model.document.get_doc(*args, **kwargs)
  File "/workspace/development/frappe-bench/apps/frappe/frappe/model/document.py", line 73, in get_doc
    controller = get_controller(doctype)
  File "/workspace/development/frappe-bench/apps/frappe/frappe/model/base_document.py", line 89, in get_controller
    return _get_controller()
  File "/workspace/development/frappe-bench/apps/frappe/frappe/model/base_document.py", line 59, in _get_controller
    module_name, custom = frappe.db.get_value(
  File "/workspace/development/frappe-bench/apps/frappe/frappe/database/database.py", line 509, in get_value
    result = self.get_values(
  File "/workspace/development/frappe-bench/apps/frappe/frappe/database/database.py", line 606, in get_values
    out = self._get_values_from_table(
  File "/workspace/development/frappe-bench/apps/frappe/frappe/database/database.py", line 835, in _get_values_from_table
    return query.run(as_dict=as_dict, debug=debug, update=update, run=run, pluck=pluck)
  File "/workspace/development/frappe-bench/apps/frappe/frappe/query_builder/utils.py", line 87, in execute_query
    result = frappe.db.sql(query, params, *args, **kwargs)  # nosemgrep
  File "/workspace/development/frappe-bench/apps/frappe/frappe/database/database.py", line 201, in sql
    self.connect()
  File "/workspace/development/frappe-bench/apps/frappe/frappe/database/database.py", line 115, in connect
    self._conn = self.get_connection()
  File "/workspace/development/frappe-bench/apps/frappe/frappe/database/mariadb/database.py", line 98, in get_connection
    conn = self._get_connection()
  File "/workspace/development/frappe-bench/apps/frappe/frappe/database/mariadb/database.py", line 104, in _get_connection
    return self.create_connection()
  File "/workspace/development/frappe-bench/apps/frappe/frappe/database/mariadb/database.py", line 107, in create_connection
    return pymysql.connect(**self.get_connection_settings())
  File "/workspace/development/frappe-bench/env/lib/python3.10/site-packages/pymysql/connections.py", line 352, in __init__
    self.connect()
  File "/workspace/development/frappe-bench/env/lib/python3.10/site-packages/pymysql/connections.py", line 636, in connect
    self._request_authentication()
  File "/workspace/development/frappe-bench/env/lib/python3.10/site-packages/pymysql/connections.py", line 911, in _request_authentication
    auth_packet = self._read_packet()
  File "/workspace/development/frappe-bench/env/lib/python3.10/site-packages/pymysql/connections.py", line 729, in _read_packet
    packet.raise_for_error()
  File "/workspace/development/frappe-bench/env/lib/python3.10/site-packages/pymysql/protocol.py", line 221, in raise_for_error
    err.raise_mysql_exception(self._data)
  File "/workspace/development/frappe-bench/env/lib/python3.10/site-packages/pymysql/err.py", line 143, in raise_mysql_exception
    raise errorclass(errno, errval)
pymysql.err.OperationalError: (1045, "Access denied for user '_7b6ff8d4fc4aba9a'@'172.21.0.6' (using password: YES)")

During handling of the above exception, another exception occurred:

Traceback (most recent call last):
  File "/workspace/development/frappe-bench/apps/frappe/frappe/utils/caching.py", line 55, in wrapper
    return frappe.local.request_cache[func][args_key]
KeyError: 5740354900026072187

During handling of the above exception, another exception occurred:

Traceback (most recent call last):
  File "/workspace/development/frappe-bench/apps/frappe/frappe/utils/caching.py", line 55, in wrapper
    return frappe.local.request_cache[func][args_key]
KeyError: 1333281032887748720

During handling of the above exception, another exception occurred:

Traceback (most recent call last):
  File "/workspace/development/frappe-bench/apps/frappe/frappe/website/serve.py", line 17, in get_response
    endpoint, renderer_instance = path_resolver.resolve()
  File "/workspace/development/frappe-bench/apps/frappe/frappe/website/path_resolver.py", line 36, in resolve
    resolve_redirect(self.path, request.query_string)
  File "/workspace/development/frappe-bench/apps/frappe/frappe/website/path_resolver.py", line 107, in resolve_redirect
    redirects = frappe.get_hooks("website_redirects")
  File "/workspace/development/frappe-bench/apps/frappe/frappe/__init__.py", line 1511, in get_hooks
    hooks = _dict(_load_app_hooks())
  File "/workspace/development/frappe-bench/apps/frappe/frappe/utils/caching.py", line 57, in wrapper
    return_val = func(*args, **kwargs)
  File "/workspace/development/frappe-bench/apps/frappe/frappe/__init__.py", line 1476, in _load_app_hooks
    apps = [app_name] if app_name else get_installed_apps(_ensure_on_bench=True)
  File "/workspace/development/frappe-bench/apps/frappe/frappe/utils/caching.py", line 57, in wrapper
    return_val = func(*args, **kwargs)
  File "/workspace/development/frappe-bench/apps/frappe/frappe/__init__.py", line 1432, in get_installed_apps
    installed = json.loads(db.get_global("installed_apps") or "[]")
  File "/workspace/development/frappe-bench/apps/frappe/frappe/database/database.py", line 975, in get_global
    return self.get_default(key, user)
  File "/workspace/development/frappe-bench/apps/frappe/frappe/database/database.py", line 979, in get_default
    d = self.get_defaults(key, parent)
  File "/workspace/development/frappe-bench/apps/frappe/frappe/database/database.py", line 995, in get_defaults
    defaults = frappe.defaults.get_defaults_for(parent)
  File "/workspace/development/frappe-bench/apps/frappe/frappe/defaults.py", line 238, in get_defaults_for
    frappe.qb.from_(table)
  File "/workspace/development/frappe-bench/apps/frappe/frappe/query_builder/utils.py", line 87, in execute_query
    result = frappe.db.sql(query, params, *args, **kwargs)  # nosemgrep
  File "/workspace/development/frappe-bench/apps/frappe/frappe/database/database.py", line 201, in sql
    self.connect()
  File "/workspace/development/frappe-bench/apps/frappe/frappe/database/database.py", line 115, in connect
    self._conn = self.get_connection()
  File "/workspace/development/frappe-bench/apps/frappe/frappe/database/mariadb/database.py", line 98, in get_connection
    conn = self._get_connection()
  File "/workspace/development/frappe-bench/apps/frappe/frappe/database/mariadb/database.py", line 104, in _get_connection
    return self.create_connection()
  File "/workspace/development/frappe-bench/apps/frappe/frappe/database/mariadb/database.py", line 107, in create_connection
    return pymysql.connect(**self.get_connection_settings())
  File "/workspace/development/frappe-bench/env/lib/python3.10/site-packages/pymysql/connections.py", line 352, in __init__
    self.connect()
  File "/workspace/development/frappe-bench/env/lib/python3.10/site-packages/pymysql/connections.py", line 636, in connect
    self._request_authentication()
  File "/workspace/development/frappe-bench/env/lib/python3.10/site-packages/pymysql/connections.py", line 911, in _request_authentication
    auth_packet = self._read_packet()
  File "/workspace/development/frappe-bench/env/lib/python3.10/site-packages/pymysql/connections.py", line 729, in _read_packet
    packet.raise_for_error()
  File "/workspace/development/frappe-bench/env/lib/python3.10/site-packages/pymysql/protocol.py", line 221, in raise_for_error
    err.raise_mysql_exception(self._data)
  File "/workspace/development/frappe-bench/env/lib/python3.10/site-packages/pymysql/err.py", line 143, in raise_mysql_exception
    raise errorclass(errno, errval)
pymysql.err.OperationalError: (1045, "Access denied for user '_7b6ff8d4fc4aba9a'@'172.21.0.6' (using password: YES)")

During handling of the above exception, another exception occurred:

Traceback (most recent call last):
  File "/workspace/development/frappe-bench/apps/frappe/frappe/utils/caching.py", line 55, in wrapper
    return frappe.local.request_cache[func][args_key]
KeyError: -2654626492847183643

During handling of the above exception, another exception occurred:

Traceback (most recent call last):
  File "/workspace/development/frappe-bench/apps/frappe/frappe/app.py", line 113, in application
    response = handle_exception(e)
  File "/workspace/development/frappe-bench/apps/frappe/frappe/app.py", line 366, in handle_exception
    response = get_response("message", http_status_code=http_status_code)
  File "/workspace/development/frappe-bench/apps/frappe/frappe/website/serve.py", line 26, in get_response
    response = ErrorPage(exception=e).render()
  File "/workspace/development/frappe-bench/apps/frappe/frappe/website/page_renderers/error_page.py", line 7, in __init__
    super().__init__(path=path, http_status_code=http_status_code)
  File "/workspace/development/frappe-bench/apps/frappe/frappe/website/page_renderers/template_page.py", line 45, in __init__
    self.set_template_path()
  File "/workspace/development/frappe-bench/apps/frappe/frappe/website/page_renderers/template_page.py", line 53, in set_template_path
    for app in frappe.get_installed_apps(frappe_last=True):
  File "/workspace/development/frappe-bench/apps/frappe/frappe/utils/caching.py", line 57, in wrapper
    return_val = func(*args, **kwargs)
  File "/workspace/development/frappe-bench/apps/frappe/frappe/__init__.py", line 1432, in get_installed_apps
    installed = json.loads(db.get_global("installed_apps") or "[]")
  File "/workspace/development/frappe-bench/apps/frappe/frappe/database/database.py", line 975, in get_global
    return self.get_default(key, user)
  File "/workspace/development/frappe-bench/apps/frappe/frappe/database/database.py", line 979, in get_default
    d = self.get_defaults(key, parent)
  File "/workspace/development/frappe-bench/apps/frappe/frappe/database/database.py", line 995, in get_defaults
    defaults = frappe.defaults.get_defaults_for(parent)
  File "/workspace/development/frappe-bench/apps/frappe/frappe/defaults.py", line 238, in get_defaults_for
    frappe.qb.from_(table)
  File "/workspace/development/frappe-bench/apps/frappe/frappe/query_builder/utils.py", line 87, in execute_query
    result = frappe.db.sql(query, params, *args, **kwargs)  # nosemgrep
  File "/workspace/development/frappe-bench/apps/frappe/frappe/database/database.py", line 201, in sql
    self.connect()
  File "/workspace/development/frappe-bench/apps/frappe/frappe/database/database.py", line 115, in connect
    self._conn = self.get_connection()
  File "/workspace/development/frappe-bench/apps/frappe/frappe/database/mariadb/database.py", line 98, in get_connection
    conn = self._get_connection()
  File "/workspace/development/frappe-bench/apps/frappe/frappe/database/mariadb/database.py", line 104, in _get_connection
    return self.create_connection()
  File "/workspace/development/frappe-bench/apps/frappe/frappe/database/mariadb/database.py", line 107, in create_connection
    return pymysql.connect(**self.get_connection_settings())
  File "/workspace/development/frappe-bench/env/lib/python3.10/site-packages/pymysql/connections.py", line 352, in __init__
    self.connect()
  File "/workspace/development/frappe-bench/env/lib/python3.10/site-packages/pymysql/connections.py", line 636, in connect
    self._request_authentication()
  File "/workspace/development/frappe-bench/env/lib/python3.10/site-packages/pymysql/connections.py", line 911, in _request_authentication
    auth_packet = self._read_packet()
  File "/workspace/development/frappe-bench/env/lib/python3.10/site-packages/pymysql/connections.py", line 729, in _read_packet
    packet.raise_for_error()
  File "/workspace/development/frappe-bench/env/lib/python3.10/site-packages/pymysql/protocol.py", line 221, in raise_for_error
    err.raise_mysql_exception(self._data)
  File "/workspace/development/frappe-bench/env/lib/python3.10/site-packages/pymysql/err.py", line 143, in raise_mysql_exception
    raise errorclass(errno, errval)
pymysql.err.OperationalError: (1045, "Access denied for user '_7b6ff8d4fc4aba9a'@'172.21.0.6' (using password: YES)")

During handling of the above exception, another exception occurred:

Traceback (most recent call last):
  File "/workspace/development/frappe-bench/apps/frappe/frappe/utils/caching.py", line 55, in wrapper
    return frappe.local.request_cache[func][args_key]
KeyError: 5740354900026072187

During handling of the above exception, another exception occurred:

Traceback (most recent call last):
  File "/workspace/development/frappe-bench/apps/frappe/frappe/utils/caching.py", line 55, in wrapper
    return frappe.local.request_cache[func][args_key]
KeyError: 1333281032887748720

During handling of the above exception, another exception occurred:

Traceback (most recent call last):
  File "/workspace/development/frappe-bench/apps/frappe/frappe/app.py", line 127, in application
    run_after_request_hooks(request, response)
  File "/workspace/development/frappe-bench/apps/frappe/frappe/app.py", line 143, in run_after_request_hooks
    for after_request_task in frappe.get_hooks("after_request"):
  File "/workspace/development/frappe-bench/apps/frappe/frappe/__init__.py", line 1511, in get_hooks
    hooks = _dict(_load_app_hooks())
  File "/workspace/development/frappe-bench/apps/frappe/frappe/utils/caching.py", line 57, in wrapper
    return_val = func(*args, **kwargs)
  File "/workspace/development/frappe-bench/apps/frappe/frappe/__init__.py", line 1476, in _load_app_hooks
    apps = [app_name] if app_name else get_installed_apps(_ensure_on_bench=True)
  File "/workspace/development/frappe-bench/apps/frappe/frappe/utils/caching.py", line 57, in wrapper
    return_val = func(*args, **kwargs)
  File "/workspace/development/frappe-bench/apps/frappe/frappe/__init__.py", line 1432, in get_installed_apps
    installed = json.loads(db.get_global("installed_apps") or "[]")
  File "/workspace/development/frappe-bench/apps/frappe/frappe/database/database.py", line 975, in get_global
    return self.get_default(key, user)
  File "/workspace/development/frappe-bench/apps/frappe/frappe/database/database.py", line 979, in get_default
    d = self.get_defaults(key, parent)
  File "/workspace/development/frappe-bench/apps/frappe/frappe/database/database.py", line 995, in get_defaults
    defaults = frappe.defaults.get_defaults_for(parent)
  File "/workspace/development/frappe-bench/apps/frappe/frappe/defaults.py", line 238, in get_defaults_for
    frappe.qb.from_(table)
  File "/workspace/development/frappe-bench/apps/frappe/frappe/query_builder/utils.py", line 87, in execute_query
    result = frappe.db.sql(query, params, *args, **kwargs)  # nosemgrep
  File "/workspace/development/frappe-bench/apps/frappe/frappe/database/database.py", line 201, in sql
    self.connect()
  File "/workspace/development/frappe-bench/apps/frappe/frappe/database/database.py", line 115, in connect
    self._conn = self.get_connection()
  File "/workspace/development/frappe-bench/apps/frappe/frappe/database/mariadb/database.py", line 98, in get_connection
    conn = self._get_connection()
  File "/workspace/development/frappe-bench/apps/frappe/frappe/database/mariadb/database.py", line 104, in _get_connection
    return self.create_connection()
  File "/workspace/development/frappe-bench/apps/frappe/frappe/database/mariadb/database.py", line 107, in create_connection
    return pymysql.connect(**self.get_connection_settings())
  File "/workspace/development/frappe-bench/env/lib/python3.10/site-packages/pymysql/connections.py", line 352, in __init__
    self.connect()
  File "/workspace/development/frappe-bench/env/lib/python3.10/site-packages/pymysql/connections.py", line 636, in connect
    self._request_authentication()
  File "/workspace/development/frappe-bench/env/lib/python3.10/site-packages/pymysql/connections.py", line 911, in _request_authentication
    auth_packet = self._read_packet()
  File "/workspace/development/frappe-bench/env/lib/python3.10/site-packages/pymysql/connections.py", line 729, in _read_packet
    packet.raise_for_error()
  File "/workspace/development/frappe-bench/env/lib/python3.10/site-packages/pymysql/protocol.py", line 221, in raise_for_error
    err.raise_mysql_exception(self._data)
  File "/workspace/development/frappe-bench/env/lib/python3.10/site-packages/pymysql/err.py", line 143, in raise_mysql_exception
    raise errorclass(errno, errval)
pymysql.err.OperationalError: (1045, "Access denied for user '_7b6ff8d4fc4aba9a'@'172.21.0.6' (using password: YES)")
